Workbook

Sheet Plantilla (equipos)
E1: Detalle de las tareas
A2: Fase | B2: Horas | C2: %
A3: Análisis funcional | B3: =SUMIF(TValoraciones[Fase],A3,TValoraciones[Horas]) | C3: =Taula5[[#This Row],[Horas]]/$B$10 | E3: Título de la propuesta: | F3: GESTIC-XXXXXX - Proyecto - Descripcion
A4: Análisis técnico | B4: =SUMIF(TValoraciones[Fase],A4,TValoraciones[Horas]) | C4: =Taula5[[#This Row],[Horas]]/$B$10
A5: Desarrollo | B5: =SUMIF(TValoraciones[Fase],A5,TValoraciones[Horas]) | C5: =Taula5[[#This Row],[Horas]]/$B$10
A6: Testing | B6: =SUMIF(TValoraciones[Fase],A6,TValoraciones[Horas]) | C6: =Taula5[[#This Row],[Horas]]/$B$10 | E6: Comentarios generales: | F6: GESTIC-XXXXXX - Proyecto - Descripcion
A7: Despliegues | B7: =SUMIF(TValoraciones[Fase],A7,TValoraciones[Horas]) | C7: =Taula5[[#This Row],[Horas]]/$B$10
A8: Gestión Conocimiento | B8: =SUMIF(TValoraciones[Fase],A8,TValoraciones[Horas]) | C8: =Taula5[[#This Row],[Horas]]/$B$10
A10: Total | B10: =SUM(Taula5[Horas]) | C10: =SUM(Taula5[%]) | E10: Fase | F10: Tarea | G10: Horas | H10: Descripción | I10: Premisas / Asunciones | J10: Comentarios internos
E11: Gestión Conocimiento | F11: Gestión | G11: =ROUNDUP(Estimador_resumen!C6,0) | H11: Daily, Reuniones de soporte, Reuniones de seguimiento
E12: Gestión Conocimiento | F12: Documentación | G12: =ROUNDUP(Estimador_resumen!C10,0) | H12: Documentacion ( JsDoc, evidencias de pruebas)
E13: Análisis técnico | F13: Análisis técnico | G13: =ROUNDUP(Estimador_resumen!C7,0) | H13: Análisis incial de requisitos, reuniones de contexto, evaluación técnica para el desarrollo de la pantalla y estimación
A14: Datos de la propuesta | E14: Desarrollo | F14: Desarrollo | G14: =ROUNDUP(Estimador_resumen!C8,0) | H14: Crear en el componente para página de administración, añadirlo en routing y en menu Crear componente formulario de Unidad departamental
E15: Testing | F15: Test unitarios | G15: =ROUNDUP(Estimador_resumen!C9,0) | H15: Ejecución de pruebas unitarias para asegurar la funcionalidad
A16: Gestic | B16: GESTIC-XXXXXX | E16: Testing | F16: Peer review | G16: =ROUNDUP(Estimador_resumen!C11,0) | H16: Revisión de código por pares
A17: Área | B17: Reg. Elect. de la Generalitat | E17: Despliegues | F17: Integración del desarrollo | G17: =ROUNDUP(Estimador_resumen!C12,0) | H17: Integración del desarrollos en GIT
A18: CI | E18: Análisis funcional | F18: Análisis funcional | G18: 1 | H18: Revisión de documentación.
A19: Año | B19: 2025
A20: Mes | B20: 9

Sheet Estimador_resumen
C1: Media
B2: INCERTIDUMBRE | C2: Sí | D2: =IFERROR(INDEX(Incertidumbre[Factor], MATCH(C2, Incertidumbre[Incertidumbre], 0)), 0)
B3: ACOPLAMIENTO | C3: No | D3: =IFERROR(INDEX(Acoplamiento[Factor], MATCH(C3, Acoplamiento[Acoplamiento], 0)), 0)
B5: NOMBRE | C5: Horas formula | D5: 0
B6: Gestión | C6: =SUM(Estimador_desglosado!I4*Ponderaciones!B19,Ponderaciones!D19*Estimador_desglosado!I4/8.5) | D6: 72
B7: Analisis técnico | C7: =PRODUCT(SUM(PRODUCT(Estimador_desglosado!I4, Ponderaciones!B20),(Ponderaciones!C20/60)),1+D2) | D7: 432
B8: Construcción | C8: =PRODUCT(SUM(Estimador_desglosado!I4,PRODUCT(Estimador_desglosado!I4, Ponderaciones!B21),(Ponderaciones!C21/60)),1+D2+D3) | D8: 144
B9: Pruebas | C9: =SUM(PRODUCT(Estimador_desglosado!I4, Ponderaciones!B22),(Ponderaciones!C22/60)) | D9: 36
B10: Documentación | C10: =SUM(PRODUCT(Estimador_desglosado!I4, Ponderaciones!B23),(Ponderaciones!C23/60)) | D10: 36
B11: Peer Review | C11: =SUM(PRODUCT(Estimador_desglosado!I4, Ponderaciones!B24),(Ponderaciones!C24/60)) | D11: =MROUND(C11, 0.25)
B12: Integración/Despliegue | C12: =SUM(PRODUCT(Estimador_desglosado!I4, Ponderaciones!B25),(Ponderaciones!C25/60)) | D12: =MROUND(C12, 0.25)

Sheet Estimador_desglosado
I3: TOTAL Puro
I4: =(SUM(I7:I1000)/60)*Ponderaciones!B16
A6: Servicios | B6: SÍ | C6: DetalleRegistroApiService | D6: 3 | E6: 12 | F6: 0 | G6: 3 | H6: 0 | I6: 6
A7: Servicios | B7: SÍ | C7: DetalleRegistroStateService | D7: 3 | E7: 12 | F7: 0 | G7: 3 | H7: 0 | I7: 6
A8: Servicios | B8: SÍ | C8: DetalleRegistroPermisosService | D8: 3 | E8: 12 | F8: 0 | G8: 3 | H8: 0 | I8: 6
A9: Servicios | B9: SÍ | C9: DocumentosApiService | D9: 3 | E9: 12 | F9: 0 | G9: 3 | H9: 0 | I9: 6
A10: Servicios | B10: SÍ | C10: DocumentosGestorService | D10: 3 | E10: 12 | F10: 0 | G10: 3 | H10: 0 | I10: 6
A11: Componentes (TS) | B11: SÍ | C11: pero | D11: 8 | E11: 15 | F11: 10 | G11: 5 | H11: 12 | I11: 30
A12: Componentes (TS) | B12: SÍ | C12: Contenedor | D12: 8 | E12: 15 | F12: 10 | G12: 5 | H12: 12 | I12: 30
A13: Componentes (TS) | B13: SÍ | C13: Fase | D13: 8 | E13: 15 | F13: 10 | G13: 5 | H13: 12 | I13: 30
A14: Componentes (TS) | B14: SÍ | C14: DetalleRegistroPageComponent | D14: 8 | E14: 15 | F14: 10 | G14: 5 | H14: 12 | I14: 30
A15: Componentes (TS) | B15: SÍ | C15: DatosRegistroRdsComponent | D15: 8 | E15: 15 | F15: 10 | G15: 5 | H15: 12 | I15: 30
A16: Componentes (TS) | B16: SÍ | C16: DatosRegistroRdeComponent | D16: 8 | E16: 15 | F16: 10 | G16: 5 | H16: 12 | I16: 30
A17: Componentes (TS) | B17: SÍ | C17: DestinoProcedenciaComponent | D17: 8 | E17: 15 | F17: 10 | G17: 5 | H17: 12 | I17: 30
... A25: Componentes (TS) | B25: SÍ | C25: CambiarTipoTransporteModalComponent | D25: 8 | E25: 15 | F25: 10 | G25: 5 | H25: 12 | I25: 30
I26: =IF(COUNTIF(Tiempos[Tipo de Tarea], A26)=0, 0, SUMPRODUCT(INDEX(Tiempos[[Propiedad]:[Regla Negocio]], MATCH(A26, Tiempos[Tipo de Tarea], 0), 0), D26:H26)) * IFERROR(INDEX(Ponderaciones!B29:B30, MATCH(B26, Ponderaciones!A29:A30, 0)), 1)
I27: =IF(COUNTIF(Tiempos[Tipo de Tarea], A27)=0, 0, SUMPRODUCT(INDEX(Tiempos[[Propiedad]:[Regla Negocio]], MATCH(A27, Tiempos[Tipo de Tarea], 0), 0), D27:H27)) * IFERROR(INDEX(Ponderaciones!B30:B31, MATCH(B27, Ponderaciones!A30:A31, 0)), 1)
I28: =IF(COUNTIF(Tiempos[Tipo de Tarea], A28)=0, 0, SUMPRODUCT(INDEX(Tiempos[[Propiedad]:[Regla Negocio]], MATCH(A28, Tiempos[Tipo de Tarea], 0), 0), D28:H28)) * IFERROR(INDEX(Ponderaciones!B32:B33, MATCH(B28, Ponderaciones!A32:A33, 0)), 1)
I29: =IF(COUNTIF(Tiempos[Tipo de Tarea], A29)=0, 0, SUMPRODUCT(INDEX(Tiempos[[Propiedad]:[Regla Negocio]], MATCH(A29, Tiempos[Tipo de Tarea], 0), 0), D29:H29)) * IFERROR(INDEX(Ponderaciones!B33:B34, MATCH(B29, Ponderaciones!A33:A34, 0)), 1)
I30: =IF(COUNTIF(Tiempos[Tipo de Tarea], A30)=0, 0, SUMPRODUCT(INDEX(Tiempos[[Propiedad]:[Regla Negocio]], MATCH(A30, Tiempos[Tipo de Tarea], 0), 0), D30:H30)) * IFERROR(INDEX(Ponderaciones!B33:B34, MATCH(B30, Ponderaciones!A33:A34, 0)), 1)
I31: =IF(COUNTIF(Tiempos[Tipo de Tarea], A31)=0, 0, SUMPRODUCT(INDEX(Tiempos[[Propiedad]:[Regla Negocio]], MATCH(A31, Tiempos[Tipo de Tarea], 0), 0), D31:H31)) * IFERROR(INDEX(Ponderaciones!B34:B35, MATCH(B31, Ponderaciones!A34:A35, 0)), 1)
I32: =IF(COUNTIF(Tiempos[Tipo de Tarea], A32)=0, 0, SUMPRODUCT(INDEX(Tiempos[[Propiedad]:[Regla Negocio]], MATCH(A32, Tiempos[Tipo de Tarea], 0), 0), D32:H32)) * IFERROR(INDEX(Ponderaciones!B36:B37, MATCH(B32, Ponderaciones!A36:A37, 0)), 1)
I33: =IF(COUNTIF(Tiempos[Tipo de Tarea], A33)=0, 0, SUMPRODUCT(INDEX(Tiempos[[Propiedad]:[Regla Negocio]], MATCH(A33, Tiempos[Tipo de Tarea], 0), 0), D33:H33)) * IFERROR(INDEX(Ponderaciones!B37:B38, MATCH(B33, Ponderaciones!A37:A38, 0)), 1)
I34: =IF(COUNTIF(Tiempos[Tipo de Tarea], A34)=0, 0, SUMPRODUCT(INDEX(Tiempos[[Propiedad]:[Regla Negocio]], MATCH(A34, Tiempos[Tipo de Tarea], 0), 0), D34:H34)) * IFERROR(INDEX(Ponderaciones!B37:B38, MATCH(B34, Ponderaciones!A37:A38, 0)), 1)
I35: =IF(COUNTIF(Tiempos[Tipo de Tarea], A35)=0, 0, SUMPRODUCT(INDEX(Tiempos[[Propiedad]:[Regla Negocio]], MATCH(A35, Tiempos[Tipo de Tarea], 0), 0), D35:H35)) * IFERROR(INDEX(Ponderaciones!B38:B39, MATCH(B35, Ponderaciones!A38:A39, 0)), 1)
I36: =IF(COUNTIF(Tiempos[Tipo de Tarea], A36)=0, 0, SUMPRODUCT(INDEX(Tiempos[[Propiedad]:[Regla Negocio]], MATCH(A36, Tiempos[Tipo de Tarea], 0), 0), D36:H36)) * IFERROR(INDEX(Ponderaciones!B40:B41, MATCH(B36, Ponderaciones!A40:A41, 0)), 1)
I37: =IF(COUNTIF(Tiempos[Tipo de Tarea], A37)=0, 0, SUMPRODUCT(INDEX(Tiempos[[Propiedad]:[Regla Negocio]], MATCH(A37, Tiempos[Tipo de Tarea], 0), 0), D37:H37)) * IFERROR(INDEX(Ponderaciones!B41:B42, MATCH(B37, Ponderaciones!A41:A42, 0)), 1)
I38: =IF(COUNTIF(Tiempos[Tipo de Tarea], A38)=0, 0, SUMPRODUCT(INDEX(Tiempos[[Propiedad]:[Regla Negocio]], MATCH(A38, Tiempos[Tipo de Tarea], 0), 0), D38:H38)) * IFERROR(INDEX(Ponderaciones!B41:B42, MATCH(B38, Ponderaciones!A41:A42, 0)), 1)
I39: =IF(COUNTIF(Tiempos[Tipo de Tarea], A39)=0, 0, SUMPRODUCT(INDEX(Tiempos[[Propiedad]:[Regla Negocio]], MATCH(A39, Tiempos[Tipo de Tarea], 0), 0), D39:H39)) * IFERROR(INDEX(Ponderaciones!B42:B43, MATCH(B39, Ponderaciones!A42:A43, 0)), 1)
I40: =IF(COUNTIF(Tiempos[Tipo de Tarea], A40)=0, 0, SUMPRODUCT(INDEX(Tiempos[[Propiedad]:[Regla Negocio]], MATCH(A40, Tiempos[Tipo de Tarea], 0), 0), D40:H40)) * IFERROR(INDEX(Ponderaciones!B44:B45, MATCH(B40, Ponderaciones!A44:A45, 0)), 1)
I41: =IF(COUNTIF(Tiempos[Tipo de Tarea], A41)=0, 0, SUMPRODUCT(INDEX(Tiempos[[Propiedad]:[Regla Negocio]], MATCH(A41, Tiempos[Tipo de Tarea], 0), 0), D41:H41)) * IFERROR(INDEX(Ponderaciones!B45:B46, MATCH(B41, Ponderaciones!A45:A46, 0)), 1)
I42: =IF(COUNTIF(Tiempos[Tipo de Tarea], A42)=0, 0, SUMPRODUCT(INDEX(Tiempos[[Propiedad]:[Regla Negocio]], MATCH(A42, Tiempos[Tipo de Tarea], 0), 0), D42:H42)) * IFERROR(INDEX(Ponderaciones!B45:B46, MATCH(B42, Ponderaciones!A45:A46, 0)), 1)
I43: =IF(COUNTIF(Tiempos[Tipo de Tarea], A43)=0, 0, SUMPRODUCT(INDEX(Tiempos[[Propiedad]:[Regla Negocio]], MATCH(A43, Tiempos[Tipo de Tarea], 0), 0), D43:H43)) * IFERROR(INDEX(Ponderaciones!B46:B47, MATCH(B43, Ponderaciones!A46:A47, 0)), 1)
I44: =IF(COUNTIF(Tiempos[Tipo de Tarea], A44)=0, 0, SUMPRODUCT(INDEX(Tiempos[[Propiedad]:[Regla Negocio]], MATCH(A44, Tiempos[Tipo de Tarea], 0), 0), D44:H44)) * IFERROR(INDEX(Ponderaciones!B48:B49, MATCH(B44, Ponderaciones!A48:A49, 0)), 1)
I45: =IF(COUNTIF(Tiempos[Tipo de Tarea], A45)=0, 0, SUMPRODUCT(INDEX(Tiempos[[Propiedad]:[Regla Negocio]], MATCH(A45, Tiempos[Tipo de Tarea], 0), 0), D45:H45)) * IFERROR(INDEX(Ponderaciones!B49:B50, MATCH(B45, Ponderaciones!A49:A50, 0)), 1)
I46: =IF(COUNTIF(Tiempos[Tipo de Tarea], A46)=0, 0, SUMPRODUCT(INDEX(Tiempos[[Propiedad]:[Regla Negocio]], MATCH(A46, Tiempos[Tipo de Tarea], 0), 0), D46:H46)) * IFERROR(INDEX(Ponderaciones!B49:B50, MATCH(B46, Ponderaciones!A49:A50, 0)), 1)
I47: =IF(COUNTIF(Tiempos[Tipo de Tarea], A47)=0, 0, SUMPRODUCT(INDEX(Tiempos[[Propiedad]:[Regla Negocio]], MATCH(A47, Tiempos[Tipo de Tarea], 0), 0), D47:H47)) * IFERROR(INDEX(Ponderaciones!B50:B51, MATCH(B47, Ponderaciones!A50:A51, 0)), 1)
I48: =IF(COUNTIF(Tiempos[Tipo de Tarea], A48)=0, 0, SUMPRODUCT(INDEX(Tiempos[[Propiedad]:[Regla Negocio]], MATCH(A48, Tiempos[Tipo de Tarea], 0), 0), D48:H48)) * IFERROR(INDEX(Ponderaciones!B52:B53, MATCH(B48, Ponderaciones!A52:A53, 0)), 1)
I49: =IF(COUNTIF(Tiempos[Tipo de Tarea], A49)=0, 0, SUMPRODUCT(INDEX(Tiempos[[Propiedad]:[Regla Negocio]], MATCH(A49, Tiempos[Tipo de Tarea], 0), 0), D49:H49)) * IFERROR(INDEX(Ponderaciones!B53:B54, MATCH(B49, Ponderaciones!A53:A54, 0)), 1)
I50: =IF(COUNTIF(Tiempos[Tipo de Tarea], A50)=0, 0, SUMPRODUCT(INDEX(Tiempos[[Propiedad]:[Regla Negocio]], MATCH(A50, Tiempos[Tipo de Tarea], 0), 0), D50:H50)) * IFERROR(INDEX(Ponderaciones!B53:B54, MATCH(B50, Ponderaciones!A53:A54, 0)), 1)
...

Sheet Ponderaciones
A1: MIS TIEMPOS
A2: Tipo de Tarea | B2: Propiedad | C2: Método | D2: Evento | E2: Integración | F2: Regla Negocio
A3: Modelo de datos | B3: 10 | C3: 15 | D3: 0 | E3: 0 | F3: 60
A4: Módulos | B4: 5 | C4: 45 | D4: 0 | E4: 30 | F4: 0
A5: Servicios | B5: 10 | C5: 15 | D5: 0 | E5: 45 | F5: 0
A6: Componentes (TS) | B6: 10 | C6: 30 | D6: 30 | E6: 45 | F6: 60
A7: Vista HTML | B7: 10 | C7: 0 | D7: 10 | E7: 0 | F7: 15
A8: Estilos SCSS | B8: 15 | C8: 30 | D8: 15 | E8: 75 | F8: 30
H10: Incertidumbre | I10: Factor
B11: Factor ajuste | C11: Tiempo min. | H11: Nula | I11: 0
A12: Nuevo | B12: 1 | C12: 0 | H12: Baja | I12: 0,07
A13: Actualización | B13: 1.5 | C13: 0 | H13: Media | I13: 0,15
H14: Alta | I14: 0,3
A15: Senior | B15: 1 | C15: 0
A16: Mid | B16: 1.5 | C16: 0
A17: Junior | B17: 2.5 | C17: 0 | H17: Acoplamiento | I17: Factor
H18: Sí | I18: 0,15
B19: 0.1 | D19: 0.5 | E19: Daily/dia | H19: No | I19: 0
A20: Analisis técnico | B20: 0.2 | C20: 45
A21: Comprensión tarea | B21: =0.05 | C21: 30
A22: Test | B22: 0.2 | C22: 30
A23: Documentación | B23: 0.1 | C23: 30
A24: Peer Reviews | B24: 0.05 | C24: 30
A25: Integración | B25: 0 | C25: 30

Sheet Hoja1

Sheet Definiciones
B2: Tipo de Tarea | C2: Elemento Cuantificable | D2: Descripcion | E2: Comentario
B3: Modelo de datos | C3: Propiedad | D3: Cada propiedad incluye declaración, inicialización y documentación (si aplica).
C4: Método | D4: Métodos incluyen getters/setters, transformación básica de datos. | E4: Tienen menor complejidad
C5: Reglas de negocio | D5: Validaciones comunes, lógica avanzada en el modelo. | E5: Tienen mayor complejidad
B6: Módulos | C6: Propiedad | D6: Configuración de imports, declarations, etc.
C7: Método | D7: Métodos como configuraciones personalizadas (guards, resolvers, etc.).
C8: Integración | D8: Configuración de integración con librerías externas o módulos de terceros.
B9: Servicios | C9: Propiedad | D9: Propiedades para estado o configuración del servicio.
C10: Método | D10: Lógica de negocio o funciones que interactúan con APIs y control de flujo de datos.
C11: Integración | D11: Tiempo necesario para conectar un servicio con APIs externas o SDKs de terceros. | E11: Definir peticiones a terceros y comprobar que funcionen
B12: Componentes (TS) | C12: Propiedad | D12: Manejar inputs (@Input()), outputs (@Output()), o variables locales.
C13: Método | D13: Lógica específica: control de eventos, manejo de datos, o interacciones del usuario.
C14: Evento | D14: Configuración de eventos (@Output, EventEmitter) y lógica asociada.
C15: Integración | D15: Comunicación entre componentes o interacción con servicios del backend.
C16: Reglas de negocio | D16: Validaciones lógicas, logica más avanzada
B17: Vista HTML | C17: Propiedad (tag) | D17: Creación de un tag básico o estructura de contenido.
C18: Evento | D18: Manejo de eventos como (click) o (change).
C19: Reglas de negocio (ngIf/For) | D19: Uso de directivas como *ngIf o *ngFor para control de lógica en la vista.
B20: Estilos SCSS | C20: Propiedad (selector) | D20: Estilizacion básica para un solo selector | E20: Definiciones con varias propieades básicas como: padding, width, color, fonts, etc.
C21: Metodo (mixins) | D21: Metodos para agurpar propiedades o incluir logica sencilla con parametrización
C22: Eventos | D22: Modificaciones para cambios de estado como focus, disabled, active, etc. | E22: Suelen ser modificaciones menores.
C23: Integración (Angular animation) | D23: Animaciones de tamaño, colores etc con Angular animatios.
C24: Reglas de negocio (Responsive) | D24: Responsive: Denición de flex, grids y media queries. Para
B28: Fases Tarea | C28: Descripcion
B29: Gestión | C29: daily y soporte si fuese necesario
B30: Analisis técnico | C30: Analisis o definción de la tarea. En tareas sencillas se profundizará menos y sirve con añadir descripicón en la tarea
B31: Compresión tarea | C31: Tiempo para que el desarrollador revise analisis/revisión y diseños
B32: Construcción | C32: Incluye la compresión por parte del desarrollador
B33: Tests | C33: Desarrollo de test unitarios
B34: Documentación | C34: Creación de storybook o documentación JsDoc
B35: PeerReview | C35: Revisión de código por pares
B36: Integración? | C36: Cajón desastre?
